Workbook

Sheet Partidas
A1: Evento | B1: Fecha | C1: Partida | D1: Jugador 1 | E1: Jugador 2 | F1: Jugador 3 | G1: Jugador 4 | H1: Jugador 5 | I1: Jugador 6 | J1: Total Jugadores | K1: Ubicación | L1: Grand Slam
A2: 1 | B2: 45294 | C2: 1 | D2: Gallo | E2: Ivo | F2: Max | G2: Sofi | H2: Gaspa | J2: =+COUNTA(D2:I2) -> 5 | K2: Ivo
A3: 1 | B3: 45294 | C3: 2 | D3: Gallo | E3: Ivo | F3: Max | G3: Sofi | H3: Gaspa | J3: =+COUNTA(D3:I3) -> 5 | K3: Ivo
A4: 1 | B4: 45294 | C4: 3 | D4: Gallo | E4: Ivo | F4: Max | G4: Sofi | J4: =+COUNTA(D4:I4) -> 4 | K4: Ivo
A5: 2 | B5: 45297 | C5: 4 | D5: Ivo | E5: Max | F5: Gaspa | G5: Gasta | J5: =+COUNTA(D5:I5) -> 4 | K5: Gaspa
A6: 2 | B6: 45297 | C6: 5 | D6: Ivo | E6: Max | F6: Gaspa | G6: Gasta | H6: Rodri | J6: =+COUNTA(D6:I6) -> 5 | K6: Gaspa
A7: 2 | B7: 45297 | C7: 6 | D7: Gallo | E7: Ivo | F7: Max | G7: Gasta | J7: =+COUNTA(D7:I7) -> 4 | K7: Gaspa
A8: 2 | B8: 45297 | C8: 7 | D8: Gallo | E8: Ivo | F8: Max | G8: Gaspa | H8: Gasta | J8: =+COUNTA(D8:I8) -> 5 | K8: Gaspa
A9: 2 | B9: 45297 | C9: 8 | D9: Gallo | E9: Ivo | F9: Max | G9: Gaspa | H9: Gasta | J9: =+COUNTA(D9:I9) -> 5 | K9: Gaspa
A10: 3 | B10: 45304 | C10: =C9+1 -> 9 | D10: Gallo | E10: Ivo | F10: Gaspa | G10: Rodri | J10: =+COUNTA(D10:I10) -> 4 | K10: Gaspa
A11: 3 | B11: 45304 | C11: =C10+1 -> 10 | D11: Gallo | E11: Ivo | F11: Gaspa | G11: Hugo | H11: Rodri | J11: =+COUNTA(D11:I11) -> 5 | K11: Gaspa
A12: 3 | B12: 45304 | C12: =C11+1 -> 11 | D12: Gallo | E12: Ivo | F12: Gaspa | G12: Hugo | H12: Rodri | I12: Sofi | J12: =+COUNTA(D12:I12) -> 6 | K12: Gaspa
A13: 3 | B13: 45304 | C13: =C12+1 -> 12 | D13: Gallo | E13: Ivo | F13: Gaspa | G13: Hugo | H13: Rodri | I13: Sofi | J13: =+COUNTA(D13:I13) -> 6 | K13: Gaspa
A14: 3 | B14: 45304 | C14: =C13+1 -> 13 | D14: Gallo | E14: Ivo | F14: Gaspa | G14: Hugo | H14: Rodri | I14: Sofi | J14: =+COUNTA(D14:I14) -> 6 | K14: Gaspa
A15: 3 | B15: 45304 | C15: 14 | D15: Gallo | E15: Ivo | F15: Gaspa | G15: Sofi | J15: =+COUNTA(D15:I15) -> 4 | K15: Gaspa
A16: 4 | B16: 45310 | C16: 15 | D16: Gallo | E16: Ivo | F16: Hugo | G16: Sofi | J16: =+COUNTA(D16:I16) -> 4 | K16: Ivo
A17: 4 | B17: 45310 | C17: 16 | D17: Gallo | E17: Ivo | F17: Hugo | G17: Sofi | J17: =+COUNTA(D17:I17) -> 4 | K17: Ivo
A18: 5 | B18: 45315 | C18: 17 | D18: Ivo | E18: Hugo | F18: Gaspa | G18: Max | J18: =+COUNTA(D18:I18) -> 4 | K18: Ivo
A19: 5 | B19: 45315 | C19: 18 | D19: Ivo | E19: Hugo | F19: Gaspa | G19: Max | J19: =+COUNTA(D19:I19) -> 4 | K19: Ivo
A20: 5 | B20: 45315 | C20: 19 | D20: Ivo | E20: Hugo | F20: Gaspa | G20: Max | J20: =+COUNTA(D20:I20) -> 4 | K20: Ivo
A21: 6 | B21: 45325 | C21: 20 | D21: Gallo | E21: Max | F21: Gaspa | G21: Hugo | H21: Ivo | I21: Rodri | J21: =+COUNTA(D21:I21) -> 6 | K21: Hugo
A22: 6 | B22: 45325 | C22: 21 | D22: Hugo | E22: Ivo | F22: Max | G22: Rodri | H22: Cami (prima Hugo) | J22: =+COUNTA(D22:I22) -> 5 | K22: Hugo
A23: 6 | B23: 45325 | C23: 22 | D23: Gallo | E23: Ivo | F23: Max | G23: Gaspa | J23: =+COUNTA(D23:I23) -> 4 | K23: Hugo
A24: 7 | B24: 45332 | C24: 23 | D24: Gallo | E24: Gaspa | F24: Max | G24: Hugo | J24: =+COUNTA(D24:I24) -> 4 | K24: Max
A25: 7 | B25: 45332 | C25: 24 | D25: Gallo | E25: Gaspa | F25: Max | G25: Hugo | J25: =+COUNTA(D25:I25) -> 4 | K25: Max
A26: 7 | B26: 45332 | C26: 25 | D26: Gallo | E26: Gaspa | F26: Max | G26: Hugo | J26: =+COUNTA(D26:I26) -> 4 | K26: Max
A27: 7 | B27: 45332 | C27: 26 | D27: Gallo | E27: Gaspa | F27: Max | G27: Hugo | J27: =+COUNTA(D27:I27) -> 4 | K27: Max
A28: 7 | B28: 45332 | C28: 27 | D28: Gallo | E28: Gaspa | F28: Max | G28: Hugo | J28: =+COUNTA(D28:I28) -> 4 | K28: Max
A29: 8 | B29: 45339 | C29: 28 | D29: Gallo | E29: Gaspa | F29: Max | G29: Sofi | J29: =+COUNTA(D29:I29) -> 4 | K29: Hugo
A30: 8 | B30: 45339 | C30: 29 | D30: Ivo | E30: Hugo | F30: Moch | G30: Rodri | H30: Beto | J30: =+COUNTA(D30:I30) -> 5 | K30: Hugo
A31: 8 | B31: 45339 | C31: 30 | D31: Gallo | E31: Gaspa | F31: Max | G31: Sofi | J31: =+COUNTA(D31:I31) -> 4 | K31: Hugo
A32: 8 | B32: 45339 | C32: 31 | D32: Gallo | E32: Ivo | F32: Hugo | G32: Sofi | H32: Max | I32: Rodri | J32: =+COUNTA(D32:I32) -> 6 | K32: Hugo
A33: 8 | B33: 45339 | C33: 32 | D33: Gallo | E33: Max | F33: Hugo | G33: Sofi | J33: =+COUNTA(D33:I33) -> 4 | K33: Hugo
A34: 9 | B34: 45343 | C34: 33 | D34: Gallo | E34: Max | F34: Hugo | G34: Ivo | H34: Rodri | J34: =+COUNTA(D34:I34) -> 5 | K34: Hugo
A35: 9 | B35: 45343 | C35: 34 | D35: Gallo | E35: Max | F35: Hugo | G35: Ivo | H35: Rodri | J35: =+COUNTA(D35:I35) -> 5 | K35: Hugo
A36: 10 | B36: 45347 | C36: 35 | D36: Gallo | E36: Max | F36: Hugo | G36: Ivo | H36: Sofi | J36: =+COUNTA(D36:I36) -> 5 | K36: Hugo
A37: 10 | B37: 45347 | C37: 36 | D37: Gallo | E37: Max | F37: Hugo | G37: Ivo | J37: =+COUNTA(D37:I37) -> 4 | K37: Hugo
A38: 10 | B38: 45347 | C38: 37 | D38: Gallo | E38: Max | F38: Hugo | G38: Ivo | J38: =+COUNTA(D38:I38) -> 4 | K38: Hugo
A39: 10 | B39: 45347 | C39: 38 | D39: Gallo | E39: Max | F39: Hugo | G39: Ivo | J39: =+COUNTA(D39:I39) -> 4 | K39: Hugo
A40: 11 | B40: 45353 | C40: 39 | D40: Gallo | E40: Max | F40: Hugo | G40: Sofi | J40: =+COUNTA(D40:I40) -> 4 | K40: Gallo
...

Sheet Resultados legacy
C1: Partida 1 (3/1) | G1: Partida 2 | M1: Partida 3 | R1: Partida 1 (6/1) | X1: Partida 2 (6/1) | AC1: Partida 3 (6/1) | AH1: Partida 4 (6/1) | AM1: Partida 4 (6/1)
B2: Jugadores | C2: Puntos tablero | D2: Ejército más grande | E2: Camino más largo | F2: PV | G2: Puntos totales | H2: Puntos tablero | I2: Ejército más grande | J2: Camino más largo | K2: PV | L2: Puntos totales | M2: Puntos tablero | N2: Ejército más grande | O2: Camino más largo | P2: PV | Q2: Puntos totales | R2: puntos tablero | S2: ejército más grande | T2: camino más largo | U2: pv | V2: puntos total | X2: puntos tablero | Y2: ejército más grande | Z2: camino más largo | AA2: pv | AB2: puntos total | AC2: puntos tablero | AD2: ejército más grande | AE2: camino más largo | AF2: pv | AG2: puntos total | AH2: puntos tablero | AI2: ejército más grande | AJ2: camino más largo | AK2: pv | AL2: puntos total | AM2: puntos tablero | AN2: ejército más grande | AO2: camino más largo | AP2: pv | AQ2: puntos total
B3: Gallo | C3: 6 | G3: =SUM(C3,F3)+SUM(D3:E3)*2 -> 6 | H3: 6 | L3: =SUM(H3,K3)+SUM(I3:J3)*2 -> 6 | M3: 7 | N3: 1 | P3: 1 | Q3: =SUM(M3,P3)+SUM(N3:O3)*2 -> 10 | V3: 0 | AB3: 0 | AC3: 7 | AF3: 3 | AG3: 10 | AH3: 7 | AJ3: 1 | AK3: 1 | AL3: 10 | AM3: 5 | AQ3: 5
B4: Ivo | C4: 5 | D4: 1 | G4: =SUM(C4,F4)+SUM(D4:E4)*2 -> 7 | H4: 7 | J4: 1 | K4: 1 | L4: =SUM(H4,K4)+SUM(I4:J4)*2 -> 10 | M4: 6 | O4: 1 | Q4: =SUM(M4,P4)+SUM(N4:O4)*2 -> 8 | R4: 6 | S4: 1 | U4: 2 | V4: 10 | X4: 4 | AB4: 4 | AC4: 5 | AE4: 1 | AG4: 7 | AH4: 4 | AK4: 1 | AL4: 5 | AM4: 7 | AN4: 1 | AP4: 1 | AQ4: 10
B5: Max | C5: 7 | G5: =SUM(C5,F5)+SUM(D5:E5)*2 -> 7 | H5: 7 | L5: =SUM(H5,K5)+SUM(I5:J5)*2 -> 7 | M5: 5 | Q5: =SUM(M5,P5)+SUM(N5:O5)*2 -> 5 | R5: 6 | V5: 6 | X5: 8 | Z5: 1 | AB5: 10 | AC5: 8 | AG5: 8 | AH5: 7 | AL5: 7 | AM5: 8 | AQ5: 8
B6: Sofi | C6: 7 | F6: 1 | G6: =SUM(C6,F6)+SUM(D6:E6)*2 -> 8 | H6: 7 | I6: 1 | L6: =SUM(H6,K6)+SUM(I6:J6)*2 -> 9 | M6: 9 | Q6: =SUM(M6,P6)+SUM(N6:O6)*2 -> 9 | V6: 0 | AB6: 0 | AG6: 0 | AL6: 8 | AQ6: 0
B7: Gaspa | C7: 8 | E7: 1 | G7: =SUM(C7,F7)+SUM(D7:E7)*2 -> 10 | H7: 7 | L7: =SUM(H7,K7)+SUM(I7:J7)*2 -> 7 | Q7: =SUM(M7,P7)+SUM(N7:O7)*2 -> 0 | R7: 7 | T7: 1 | V7: 9 | X7: 5 | AB7: 5 | AG7: 0 | AH7: 5 | AI7: 1 | AK7: 1 | AL7: 5 | AM7: 4 | AQ7: 4
B8: Gasta | R8: 4 | U8: 2 | V8: 6 | X8: 6 | AA8: 1 | AB8: 7 | AC8: 5 | AG8: 5 | AH8: 5 | AL8: 0 | AM8: 6 | AO8: 1 | AQ8: 8
B9: Rodri | V9: 0 | X9: 5 | Y9: 1 | AA9: 1 | AB9: 8 | AG9: 0 | AL9: 0 | AQ9: 0
V10: 0 | AB10: 0 | AG10: 0 | AL10: 0 | AQ10: 0

Sheet Resultados dashboard
A1: Fecha | B1: Partida | C1: Jugadores | D1: Puntos tablero | E1: PV | F1: Ejército más grande | G1: Camino más largo | H1: Puntos totales | I1: Rank por partida | J1: Penalidad
A2: 45294 | B2: 1 | C2: Gallo | D2: 6 | H2: =+SUM(D2:E2)+2*SUM(F2:G2)+J2 -> 6 | I2: =COUNTIFS($B$2:$B$1075,B2,$H$2:$H$1075,">" & H2)+1 -> 5
A3: 45294 | B3: 1 | C3: Ivo | D3: 5 | F3: 1 | H3: =+SUM(D3:E3)+2*SUM(F3:G3)+J3 -> 7 | I3: =COUNTIFS($B$2:$B$1075,B3,$H$2:$H$1075,">" & H3)+1 -> 3
A4: 45294 | B4: 1 | C4: Max | D4: 7 | H4: =+SUM(D4:E4)+2*SUM(F4:G4)+J4 -> 7 | I4: =COUNTIFS($B$2:$B$1075,B4,$H$2:$H$1075,">" & H4)+1 -> 3
A5: 45294 | B5: 1 | C5: Sofi | D5: 7 | E5: 1 | H5: =+SUM(D5:E5)+2*SUM(F5:G5)+J5 -> 8 | I5: =COUNTIFS($B$2:$B$1075,B5,$H$2:$H$1075,">" & H5)+1 -> 2
A6: 45294 | B6: 1 | C6: Gaspa | D6: 8 | G6: 1 | H6: =+SUM(D6:E6)+2*SUM(F6:G6)+J6 -> 10 | I6: =COUNTIFS($B$2:$B$1075,B6,$H$2:$H$1075,">" & H6)+1 -> 1
A7: 45294 | B7: 2 | C7: Gallo | D7: 6 | H7: =+SUM(D7:E7)+2*SUM(F7:G7)+J7 -> 6 | I7: =COUNTIFS($B$2:$B$1075,B7,$H$2:$H$1075,">" & H7)+1 -> 5
A8: 45294 | B8: 2 | C8: Ivo | D8: 7 | E8: 1 | G8: 1 | H8: =+SUM(D8:E8)+2*SUM(F8:G8)+J8 -> 10 | I8: =COUNTIFS($B$2:$B$1075,B8,$H$2:$H$1075,">" & H8)+1 -> 1
A9: 45294 | B9: 2 | C9: Max | D9: 7 | H9: =+SUM(D9:E9)+2*SUM(F9:G9)+J9 -> 7 | I9: =COUNTIFS($B$2:$B$1075,B9,$H$2:$H$1075,">" & H9)+1 -> 3
A10: 45294 | B10: 2 | C10: Sofi | D10: 7 | F10: 1 | H10: =+SUM(D10:E10)+2*SUM(F10:G10)+J10 -> 9 | I10: =COUNTIFS($B$2:$B$1075,B10,$H$2:$H$1075,">" & H10)+1 -> 2
A11: 45294 | B11: 2 | C11: Gaspa | D11: 7 | H11: =+SUM(D11:E11)+2*SUM(F11:G11)+J11 -> 7 | I11: =COUNTIFS($B$2:$B$1075,B11,$H$2:$H$1075,">" & H11)+1 -> 3
A12: 45294 | B12: 3 | C12: Gallo | D12: 7 | E12: 1 | F12: 1 | H12: =+SUM(D12:E12)+2*SUM(F12:G12)+J12 -> 10 | I12: =COUNTIFS($B$2:$B$1075,B12,$H$2:$H$1075,">" & H12)+1 -> 1
A13: 45294 | B13: 3 | C13: Ivo | D13: 6 | G13: 1 | H13: =+SUM(D13:E13)+2*SUM(F13:G13)+J13 -> 8 | I13: =COUNTIFS($B$2:$B$1075,B13,$H$2:$H$1075,">" & H13)+1 -> 3
A14: 45294 | B14: 3 | C14: Max | D14: 5 | H14: =+SUM(D14:E14)+2*SUM(F14:G14)+J14 -> 5 | I14: =COUNTIFS($B$2:$B$1075,B14,$H$2:$H$1075,">" & H14)+1 -> 4
A15: 45294 | B15: 3 | C15: Sofi | D15: 9 | H15: =+SUM(D15:E15)+2*SUM(F15:G15)+J15 -> 9 | I15: =COUNTIFS($B$2:$B$1075,B15,$H$2:$H$1075,">" & H15)+1 -> 2
A16: 45297 | B16: 4 | C16: Ivo | D16: 6 | E16: 2 | F16: 1 | H16: =+SUM(D16:E16)+2*SUM(F16:G16)+J16 -> 10 | I16: =COUNTIFS($B$2:$B$1075,B16,$H$2:$H$1075,">" & H16)+1 -> 1
A17: 45297 | B17: 4 | C17: Max | D17: 6 | H17: =+SUM(D17:E17)+2*SUM(F17:G17)+J17 -> 6 | I17: =COUNTIFS($B$2:$B$1075,B17,$H$2:$H$1075,">" & H17)+1 -> 3
A18: 45297 | B18: 4 | C18: Gaspa | D18: 7 | G18: 1 | H18: =+SUM(D18:E18)+2*SUM(F18:G18)+J18 -> 9 | I18: =COUNTIFS($B$2:$B$1075,B18,$H$2:$H$1075,">" & H18)+1 -> 2
A19: 45297 | B19: 4 | C19: Gasta | D19: 4 | E19: 2 | H19: =+SUM(D19:E19)+2*SUM(F19:G19)+J19 -> 6 | I19: =COUNTIFS($B$2:$B$1075,B19,$H$2:$H$1075,">" & H19)+1 -> 3
A20: 45297 | B20: 5 | C20: Ivo | D20: 4 | H20: =+SUM(D20:E20)+2*SUM(F20:G20)+J20 -> 4 | I20: =COUNTIFS($B$2:$B$1075,B20,$H$2:$H$1075,">" & H20)+1 -> 5
A21: 45297 | B21: 5 | C21: Max | D21: 8 | G21: 1 | H21: =+SUM(D21:E21)+2*SUM(F21:G21)+J21 -> 10 | I21: =COUNTIFS($B$2:$B$1075,B21,$H$2:$H$1075,">" & H21)+1 -> 1
A22: 45297 | B22: 5 | C22: Gaspa | D22: 5 | H22: =+SUM(D22:E22)+2*SUM(F22:G22)+J22 -> 5 | I22: =COUNTIFS($B$2:$B$1075,B22,$H$2:$H$1075,">" & H22)+1 -> 4
A23: 45297 | B23: 5 | C23: Gasta | D23: 6 | E23: 1 | H23: =+SUM(D23:E23)+2*SUM(F23:G23)+J23 -> 7 | I23: =COUNTIFS($B$2:$B$1075,B23,$H$2:$H$1075,">" & H23)+1 -> 3
A24: 45297 | B24: 5 | C24: Rodri | D24: 5 | E24: 1 | F24: 1 | H24: =+SUM(D24:E24)+2*SUM(F24:G24)+J24 -> 8 | I24: =COUNTIFS($B$2:$B$1075,B24,$H$2:$H$1075,">" & H24)+1 -> 2
A25: 45297 | B25: 6 | C25: Gallo | D25: 7 | E25: 3 | H25: =+SUM(D25:E25)+2*SUM(F25:G25)+J25 -> 10 | I25: =COUNTIFS($B$2:$B$1075,B25,$H$2:$H$1075,">" & H25)+1 -> 1
A26: 45297 | B26: 6 | C26: Ivo | D26: 5 | G26: 1 | H26: =+SUM(D26:E26)+2*SUM(F26:G26)+J26 -> 7 | I26: =COUNTIFS($B$2:$B$1075,B26,$H$2:$H$1075,">" & H26)+1 -> 3
A27: 45297 | B27: 6 | C27: Max | D27: 8 | H27: =+SUM(D27:E27)+2*SUM(F27:G27)+J27 -> 8 | I27: =COUNTIFS($B$2:$B$1075,B27,$H$2:$H$1075,">" & H27)+1 -> 2
A28: 45297 | B28: 6 | C28: Gasta | D28: 5 | H28: =+SUM(D28:E28)+2*SUM(F28:G28)+J28 -> 5 | I28: =COUNTIFS($B$2:$B$1075,B28,$H$2:$H$1075,">" & H28)+1 -> 4
A29: 45297 | B29: 7 | C29: Gallo | D29: 7 | E29: 1 | G29: 1 | H29: =+SUM(D29:E29)+2*SUM(F29:G29)+J29 -> 10 | I29: =COUNTIFS($B$2:$B$1075,B29,$H$2:$H$1075,">" & H29)+1 -> 1
A30: 45297 | B30: 7 | C30: Ivo | D30: 4 | E30: 1 | H30: =+SUM(D30:E30)+2*SUM(F30:G30)+J30 -> 5 | I30: =COUNTIFS($B$2:$B$1075,B30,$H$2:$H$1075,">" & H30)+1 -> 4
A31: 45297 | B31: 7 | C31: Max | D31: 7 | H31: =+SUM(D31:E31)+2*SUM(F31:G31)+J31 -> 7 | I31: =COUNTIFS($B$2:$B$1075,B31,$H$2:$H$1075,">" & H31)+1 -> 3
A32: 45297 | B32: 7 | C32: Gaspa | D32: 5 | E32: 1 | F32: 1 | H32: =+SUM(D32:E32)+2*SUM(F32:G32)+J32 -> 8 | I32: =COUNTIFS($B$2:$B$1075,B32,$H$2:$H$1075,">" & H32)+1 -> 2
A33: 45297 | B33: 7 | C33: Gasta | D33: 5 | H33: =+SUM(D33:E33)+2*SUM(F33:G33)+J33 -> 5 | I33: =COUNTIFS($B$2:$B$1075,B33,$H$2:$H$1075,">" & H33)+1 -> 4
A34: 45297 | B34: 8 | C34: Gallo | D34: 5 | H34: =+SUM(D34:E34)+2*SUM(F34:G34)+J34 -> 5 | I34: =COUNTIFS($B$2:$B$1075,B34,$H$2:$H$1075,">" & H34)+1 -> 4
A35: 45297 | B35: 8 | C35: Ivo | D35: 7 | E35: 1 | F35: 1 | H35: =+SUM(D35:E35)+2*SUM(F35:G35)+J35 -> 10 | I35: =COUNTIFS($B$2:$B$1075,B35,$H$2:$H$1075,">" & H35)+1 -> 1
A36: 45297 | B36: 8 | C36: Max | D36: 8 | H36: =+SUM(D36:E36)+2*SUM(F36:G36)+J36 -> 8 | I36: =COUNTIFS($B$2:$B$1075,B36,$H$2:$H$1075,">" & H36)+1 -> 2
A37: 45297 | B37: 8 | C37: Gaspa | D37: 4 | H37: =+SUM(D37:E37)+2*SUM(F37:G37)+J37 -> 4 | I37: =COUNTIFS($B$2:$B$1075,B37,$H$2:$H$1075,">" & H37)+1 -> 5
A38: 45297 | B38: 8 | C38: Gasta | D38: 6 | G38: 1 | H38: =+SUM(D38:E38)+2*SUM(F38:G38)+J38 -> 8 | I38: =COUNTIFS($B$2:$B$1075,B38,$H$2:$H$1075,">" & H38)+1 -> 2
A39: {=+INDEX(Partidas!$A:$J,MATCH('Resultados dashboard'!$B39,Partidas!$C:$C,0),2)} -> 45304 | B39: =+IF(COUNTIF($B$2:B38,B38)=VLOOKUP(B38,Partidas!$C:$J,8,0),B38+1,B38) -> 9 | C39: {=+INDEX(Partidas!$A:$J,MATCH('Resultados dashboard'!$B39,Partidas!$C:$C,0),3+COUNTIF($B$2:B39,'Resultados dashboard'!$B39))} -> Gallo | D39: 6 | F39: 1 | H39: =+SUM(D39:E39)+2*SUM(F39:G39)+J39 -> 8 | I39: =COUNTIFS($B$2:$B$1075,B39,$H$2:$H$1075,">" & H39)+1 -> 2
A40: {=+INDEX(Partidas!$A:$J,MATCH('Resultados dashboard'!$B40,Partidas!$C:$C,0),2)} -> 45304 | B40: =+IF(COUNTIF($B$2:B39,B39)=VLOOKUP(B39,Partidas!$C:$J,8,0),B39+1,B39) -> 9 | C40: {=+INDEX(Partidas!$A:$J,MATCH('Resultados dashboard'!$B40,Partidas!$C:$C,0),3+COUNTIF($B$2:B40,'Resultados dashboard'!$B40))} -> Ivo | D40: 5 | E40: 1 | H40: =+SUM(D40:E40)+2*SUM(F40:G40)+J40 -> 6 | I40: =COUNTIFS($B$2:$B$1075,B40,$H$2:$H$1075,">" & H40)+1 -> 3
...
